Workbook
Name analyse: #REF!
Name EVALUATİON: #REF!
Name Segment_Agent: #N/A
Name Segment_date: #N/A
Name tableau: #REF!

Sheet APC
A1: date | B1: nom de la page | C1: campagne | D1: Agent | E1: prospet | F1: Ventes | G1: Depence | H1: chiffre d affaire | I1: commission | J1: TC | K1: Colonne1
A2: 27,04,2026 | B2: Boutique de Soin | C2: Moulinex/marmite | D2: Taadhuma | E2: 18 | F2: 1 | G2: 1.63 | J2: =Tableau3[[#This Row],[Ventes]]/Tableau3[[#This Row],[prospet]] -> 0.055555556
A3: 27,04,2026 | B3: Mustak Market | C3: Moulinex/marmite | D3: Takwim | E3: 12 | F3: 2 | G3: 1.7 | J3: =Tableau3[[#This Row],[Ventes]]/Tableau3[[#This Row],[prospet]] -> 0.16666667
A4: 27,04,2026 | B4: RMAA shop | C4: moulinex a sec/huile | D4: Rahma | E4: 10 | F4: 2 | G4: 1.8 | J4: =Tableau3[[#This Row],[Ventes]]/Tableau3[[#This Row],[prospet]] -> 0.2
A5: 27,04,2026 | B5: Ben Store | C5: marmite/huile/prise de poids | D5: Ben | E5: 17 | F5: 2 | G5: 1.31 | J5: =Tableau3[[#This Row],[Ventes]]/Tableau3[[#This Row],[prospet]] -> 0.11764706
A6: 27,04,2026 | B6: Richma Shop | C6: café/marmite | D6: Richma | E6: 11 | F6: 2 | G6: 1.56 | J6: =Tableau3[[#This Row],[Ventes]]/Tableau3[[#This Row],[prospet]] -> 0.18181818
A7: 27,04,2026 | B7: Hissanı | C7: savon soap/café | D7: Hissanı | E7: 4 | F7: Na | G7: 0.58 | J7: =Tableau3[[#This Row],[Ventes]]/Tableau3[[#This Row],[prospet]] -> #VALUE!
A8: 27,04,2026 | B8: Asna | C8: savon soap/casserole | D8: Asna | E8: 13 | F8: Na | G8: 1.36 | J8: =Tableau3[[#This Row],[Ventes]]/Tableau3[[#This Row],[prospet]] -> #VALUE!
A9: 27,04,2026 | B9: Nadjma | C9: moulinex a sec/casserole | D9: Nadjma | E9: 22 | F9: Na | G9: 2.87 | J9: =Tableau3[[#This Row],[Ventes]]/Tableau3[[#This Row],[prospet]] -> #VALUE!
A10: 28,04,2026 | B10: Boutique de Soin | C10: Moulinex/marmite | D10: Taadhuma | E10: 18 | F10: 2 | G10: 1.63 | J10: =Tableau3[[#This Row],[Ventes]]/Tableau3[[#This Row],[prospet]] -> 0.11111111
A11: 28,04,2026 | B11: Mustak Market | C11: Moulinex/marmite | D11: Takwim | E11: 23 | F11: 0 | G11: 2.51 | J11: =Tableau3[[#This Row],[Ventes]]/Tableau3[[#This Row],[prospet]] -> 0
A12: 28,04,2026 | B12: RMAA shop | C12: moulinex a sec/huile | D12: Rahma | E12: 12 | F12: 1 | G12: 1.47 | J12: =Tableau3[[#This Row],[Ventes]]/Tableau3[[#This Row],[prospet]] -> 0.083333333
A13: 28,04,2026 | B13: Ben Store | C13: marmite/huile/prise de poids | D13: Ben | E13: 31 | F13: 1 | G13: 2.73 | J13: =Tableau3[[#This Row],[Ventes]]/Tableau3[[#This Row],[prospet]] -> 0.032258065
A14: 28,04,2026 | B14: Richma Shop | C14: café/marmite | D14: Richma | E14: 21 | F14: 1 | G14: 2.87 | J14: =Tableau3[[#This Row],[Ventes]]/Tableau3[[#This Row],[prospet]] -> 0.047619048
A15: 28,04,2026 | B15: Asna | C15: savon soap/casserole | D15: Asna | E15: 12 | F15: Na | G15: 2.21 | J15: =Tableau3[[#This Row],[Ventes]]/Tableau3[[#This Row],[prospet]] -> #VALUE!
A16: 28,04,2026 | B16: Nadjma | C16: moulinex a sec/casserole | D16: Nadjma | E16: 21 | F16: Na | G16: 3.48 | J16: =Tableau3[[#This Row],[Ventes]]/Tableau3[[#This Row],[prospet]] -> #VALUE!
A17: 28,04,2026 | B17: Hissani | C17: Café/savon | D17: Hissanı | E17: 40 | F17: 0 | G17: 3.22 | J17: =Tableau3[[#This Row],[Ventes]]/Tableau3[[#This Row],[prospet]] -> 0
A18: 29,04,2026 | B18: Boutique de Soin | C18: Moulinex/marmite | D18: Taadhuma | E18: 24 | F18: 3 | G18: 3.03 | J18: =Tableau3[[#This Row],[Ventes]]/Tableau3[[#This Row],[prospet]] -> 0.125
A19: 29,04,2026 | B19: Mustak Market | C19: Moulinex/marmite | D19: Takwim | E19: 13 | F19: 1 | G19: 2.53 | J19: =Tableau3[[#This Row],[Ventes]]/Tableau3[[#This Row],[prospet]] -> 0.076923077
A20: 29,04,2026 | B20: RMAA shop | C20: moulinex a sec/huile | D20: Rahma | E20: 18 | F20: 0 | G20: 3.03 | J20: =Tableau3[[#This Row],[Ventes]]/Tableau3[[#This Row],[prospet]] -> 0
A21: 29,04,2026 | B21: Ben Store | C21: marmite/huile/prise de poids | D21: Ben | E21: 28 | F21: 1 | G21: 2.45 | J21: =Tableau3[[#This Row],[Ventes]]/Tableau3[[#This Row],[prospet]] -> 0.035714286
A22: 29,04,2026 | B22: Richma Shop | C22: café/marmite | D22: Richma | E22: 62 | F22: 1 | G22: 4.66 | J22: =Tableau3[[#This Row],[Ventes]]/Tableau3[[#This Row],[prospet]] -> 0.016129032
A23: 29,04,2026 | B23: Hissanı | C23: savon soap/café | D23: Hissanı | E23: 40 | F23: NA | G23: 2.33 | J23: =Tableau3[[#This Row],[Ventes]]/Tableau3[[#This Row],[prospet]] -> #VALUE!
A24: 29,04,2026 | B24: Asna | C24: savon soap/casserole | D24: Asna | E24: 32 | F24: NA | G24: 3.03 | J24: =Tableau3[[#This Row],[Ventes]]/Tableau3[[#This Row],[prospet]] -> #VALUE!
A25: 29,04,2026 | B25: Nadjma | C25: moulinex a sec/casserole | D25: Nadjma | E25: 13 | F25: NA | G25: 1.97 | J25: =Tableau3[[#This Row],[Ventes]]/Tableau3[[#This Row],[prospet]] -> #VALUE!
A26: 29,04,2026 | B26: Mufti | C26: Café longrish | D26: Mufti | E26: 12 | F26: NA | G26: 1.4 | J26: =Tableau3[[#This Row],[Ventes]]/Tableau3[[#This Row],[prospet]] -> #VALUE!
A27: 30,04,2026 | B27: Boutique de Soin | C27: Moulinex/marmite | D27: Taadhuma | E27: 27 | F27: 2 | G27: 2.93 | J27: =Tableau3[[#This Row],[Ventes]]/Tableau3[[#This Row],[prospet]] -> 0.074074074
A28: 30,04,2026 | B28: Mustak Market | C28: Moulinex/marmite | D28: Takwim | E28: 18 | F28: 0 | G28: 2.44 | J28: =Tableau3[[#This Row],[Ventes]]/Tableau3[[#This Row],[prospet]] -> 0
A29: 30,04,2026 | B29: RMAA shop | C29: moulinex a sec/huile | D29: Rahma | E29: 15 | F29: 1 | G29: 2.65 | J29: =Tableau3[[#This Row],[Ventes]]/Tableau3[[#This Row],[prospet]] -> 0.066666667
A30: 30,04,2026 | B30: Ben Store | C30: marmite/huile/prise de poids | D30: Ben | E30: 18 | F30: 1 | G30: 2.6 | J30: =Tableau3[[#This Row],[Ventes]]/Tableau3[[#This Row],[prospet]] -> 0.055555556
A31: 30,04,2026 | B31: Richma Shop | C31: café/marmite | D31: Richma | E31: 37 | F31: 2 | G31: 2.78 | J31: =Tableau3[[#This Row],[Ventes]]/Tableau3[[#This Row],[prospet]] -> 0.054054054
A32: 30,04,2026 | B32: HIssanı | C32: savon soap/café | D32: Hissanı | E32: 2 | F32: NA | G32: 2.34 | J32: =Tableau3[[#This Row],[Ventes]]/Tableau3[[#This Row],[prospet]] -> #VALUE!
A33: 30,04,2026 | B33: Asna | C33: savon soap/casserole | D33: Asna | E33: 9 | F33: NA | G33: 2.87 | J33: =Tableau3[[#This Row],[Ventes]]/Tableau3[[#This Row],[prospet]] -> #VALUE!
A34: 30,04,2026 | B34: Nadjma | C34: moulinex a sec/casserole | D34: Nadjma | E34: 11 | F34: NA | G34: 2.11 | J34: =Tableau3[[#This Row],[Ventes]]/Tableau3[[#This Row],[prospet]] -> #VALUE!
A35: 30,04,2026 | B35: Mufti | C35: Café longrish | D35: Mufti | E35: 18 | F35: NA | G35: 2.35 | J35: =Tableau3[[#This Row],[Ventes]]/Tableau3[[#This Row],[prospet]] -> #VALUE!
A36: 01,05,2026 | B36: Boutique de Soin | C36: Moulinex/marmite | D36: Taadhuma | E36: 10 | F36: 2 | G36: 2.33 | J36: =Tableau3[[#This Row],[Ventes]]/Tableau3[[#This Row],[prospet]] -> 0.2
A37: 01,05,2026 | B37: Mustak Market | C37: Moulinex/marmite | D37: Takwim | E37: 25 | F37: 2 | G37: 4.01 | J37: =Tableau3[[#This Row],[Ventes]]/Tableau3[[#This Row],[prospet]] -> 0.08
A38: 01,05,2026 | B38: RMAA shop | C38: moulinex a sec/huile | D38: Rahma | E38: 23 | F38: 1 | G38: 2.47 | J38: =Tableau3[[#This Row],[Ventes]]/Tableau3[[#This Row],[prospet]] -> 0.043478261
A39: 01,05,2026 | B39: Ben Store | C39: marmite/huile/prise de poids | D39: Ben | E39: 8 | F39: 2 | G39: 1.7 | J39: =Tableau3[[#This Row],[Ventes]]/Tableau3[[#This Row],[prospet]] -> 0.25
A40: 01,05,2026 | B40: Richma Shop | C40: café/marmite | D40: Richma | E40: 23 | F40: 0 | G40: 2.36 | J40: =Tableau3[[#This Row],[Ventes]]/Tableau3[[#This Row],[prospet]] -> 0
...

Sheet TCD-AGENT
A2: date | B2: (Plusieurs éléments)
A4: Étiquettes de lignes | B4: Somme de prospet | C4: Somme de Depence | D4: Somme de chiffre d affaire | E4: Somme de Ventes | F4: TAUX DE COMVERSİON
A5: Ben | B5: 99 | C5: 5.14 | D5: 14000 | E5: 2 | F5: 0.02020202
A6: Mufti | B6: 52 | C6: 4.53 | D6: 56500 | E6: 5 | F6: 0.096153846
A7: nayla | B7: 66 | C7: 3.87 | D7: 17500 | E7: 1 | F7: 0.015151515
A8: Taadhuma | B8: 205 | C8: 8.59 | D8: 56500 | E8: 6 | F8: 0.029268293
A9: Thamarati | B9: 39 | C9: 4.09 | D9: 5000 | E9: 1 | F9: 0.025641026
A10: loutfat | B10: 129 | C10: 6.84 | D10: 100500 | E10: 10 | F10: 0.07751938
A11: MARİAME | B11: 44 | C11: 1.67 | F11: 0
A12: rachida | B12: 36 | C12: 3.58 | F12: 0
A13: amine | B13: 10 | C13: 0.75 | F13: 0
A14: kalathoume | B14: 113 | C14: 4.86 | D14: 77500 | E14: 7 | F14: 0.061946903
A15: Total général | B15: 793 | C15: 43.92 | D15: 327500 | E15: 32 | F15: 0.04035309
A25: MOİS | B25: POSPECTS | C25: DEPENSES | D25: VENTES | E25: COMİSSİONS | F25: CHİFFRE D AFFAİRES | G25: TC
A26: MAİ | B26: =SUM(APC!E45:E277) -> 2682 | C26: =SUM(APC!G45:G277) -> 302.143 | D26: =SUM(APC!F45:F277) -> 159
A27: JUİN | B27: =SUM(APC!E278:E847) -> 6054 | C27: =SUM(APC!G278:G847) -> 617.8823 | D27: =SUM(APC!F278:F847) -> 465 | E27: =SUM(APC!I296:I847) -> 752750 | F27: =SUM(APC!H288:H847) -> 3900500 | G27: =D27/B27 -> 0.076808722
A69: MAİ | B69: =SUM(APC!E45:E277) -> 2682
A70: JUİN

Sheet Feuil2
A3: Étiquettes de lignes | B3: Somme de QT | C3: Somme de MONTANT | D3: Somme de MONTANT COMMİSSİON
A4: Asna | B4: 1 | C4: 8000 | D4: 0
A5: beny | B5: 4 | C5: 54500 | D5: 1500
A6: Faydhoiti | B6: 1 | C6: 7500 | D6: 0
A7: Hdidja | B7: 1 | C7: 11500 | D7: 0
A8: Kalathoumi | B8: 4 | C8: 42500 | D8: 1500
A9: Loutfat | B9: 3 | C9: 37500 | D9: 6500
A10: loutfia | B10: 3 | C10: 28000 | D10: 3000
A11: Mariam | B11: 1 | C11: 7500 | D11: 0
A12: Thadhuma | B12: 6 | C12: 51000 | D12: 4500
A13: Thamaratie | B13: 1 | C13: 17500 | D13: 0
A14: Total général | B14: 25 | C14: 265500 | D14: 17000

Sheet Feuil1
A1: DATE | B1: NOME VEDEURES | C1: PRODUIT | D1: QT | E1: PRIX | F1: MONTANT | G1: MVOLA | H1: PRIX COM | I1: MONTANT COMMİSSİON
A2: 46218.072 | B2: Loutfat | C2: the vert | D2: 1 | E2: 12500 | F2: =SUM(E2*D2) -> 12500 | H2: 2500 | I2: =SUM(H2*D2) -> 2500
A3: 46218.072 | B3: loutfia | C3: vitamine c | D3: 1 | E3: 8000 | F3: =SUM(E3*D3) -> 8000 | H3: 1500 | I3: =SUM(H3*D3) -> 1500
A4: 46218.072 | B4: beny | C4: gel orange | D4: 1 | E4: 12500 | F4: =SUM(E4*D4) -> 12500 | H4: 1500 | I4: =SUM(H4*D4) -> 1500
A5: 46218.072 | B5: Thadhuma | C5: savon noir | D5: 1 | E5: 5000 | F5: =SUM(E5*D5) -> 5000 | H5: 1000 | I5: =SUM(H5*D5) -> 1000
A6: 46218.072 | B6: Thadhuma | C6: Creme sod | D6: 1 | E6: 10000 | F6: =SUM(E6*D6) -> 10000 | I6: =SUM(H6*D6) -> 0
A7: 46218.072 | B7: Thadhuma | C7: hend creme | D7: 1 | E7: 7500 | F7: =SUM(E7*D7) -> 7500 | I7: =SUM(H7*D7) -> 0
A8: 46218.072 | B8: Thadhuma | C8: prebiotique | D8: 1 | E8: 17500 | F8: =SUM(E8*D8) -> 17500 | H8: 2500 | I8: =SUM(H8*D8) -> 2500
A9: 46218.072 | B9: Hdidja | C9: Creme rejenissant | D9: 1 | E9: 11500 | F9: =SUM(E9*D9) -> 11500 | I9: =SUM(H9*D9) -> 0
A10: 46218.072 | B10: Kalathoumi | C10: hend creme | D10: 1 | E10: 7500 | F10: =SUM(E10*D10) -> 7500 | I10: =SUM(H10*D10) -> 0
A11: 46218.072 | B11: Kalathoumi | C11: gel orange | D11: 1 | E11: 12500 | F11: =SUM(E11*D11) -> 12500 | H11: 1500 | I11: =SUM(H11*D11) -> 1500
A12: 46218.072 | B12: Kalathoumi | C12: Masque collagen | D12: 1 | E12: 10000 | F12: =SUM(E12*D12) -> 10000 | I12: =SUM(H12*D12) -> 0
A13: 46218.072 | B13: Asna | C13: vitamin c | D13: 1 | E13: 8000 | F13: =SUM(E13*D13) -> 8000 | I13: =SUM(H13*D13) -> 0
A14: 46218.072 | B14: Thadhuma | C14: dentifrice | D14: 1 | E14: 7000 | F14: =SUM(E14*D14) -> 7000 | I14: =SUM(H14*D14) -> 0
A15: 46218.072 | B15: Loutfia | C15: gel orange | D15: 1 | E15: 12000 | F15: =SUM(E15*D15) -> 12000 | H15: 1500 | I15: =SUM(H15*D15) -> 1500
A16: 46218.072 | B16: Loutfia | C16: vitamine c | D16: 1 | E16: 8000 | F16: =SUM(E16*D16) -> 8000 | I16: =SUM(H16*D16) -> 0
A17: 46218.072 | B17: Thadhuma | C17: savon au riz | D17: 1 | E17: 4000 | F17: =SUM(E17*D17) -> 4000 | H17: 1000 | I17: =SUM(H17*D17) -> 1000
A18: 46218.072 | B18: Mariam | C18: huil de serpent | D18: 1 | E18: 7500 | F18: =SUM(E18*D18) -> 7500 | I18: =SUM(H18*D18) -> 0
A19: 46218.072 | B19: Faydhoiti | C19: hand creme | D19: 1 | E19: 7500 | F19: =SUM(E19*D19) -> 7500 | I19: =SUM(H19*D19) -> 0
A20: 46218.072 | B20: loutfat | C20: Gel orange | D20: 1 | E20: 12500 | F20: =SUM(E20*D20) -> 12500 | H20: 1500 | I20: =SUM(H20*D20) -> 1500
A21: 46218.072 | B21: Beny | C21: Libao | D21: 1 | E21: 30000 | F21: =SUM(E21*D21) -> 30000 | I21: =SUM(H21*D21) -> 0
A22: 46218.072 | B22: Beny | C22: savon au riz | D22: 1 | E22: 4000 | F22: =SUM(E22*D22) -> 4000 | I22: =SUM(H22*D22) -> 0
A23: 46218.072 | B23: Beny | C23: Vitaminc | D23: 1 | E23: 8000 | F23: =SUM(E23*D23) -> 8000 | I23: =SUM(H23*D23) -> 0
A24: 46218.072 | B24: Kalathoumi | C24: Gel orange | D24: 1 | E24: 12500 | F24: =SUM(E24*D24) -> 12500 | I24: =SUM(H24*D24) -> 0
A25: 46218.072 | B25: Thamaratie | C25: huil de serpent et champooin | D25: 1 | E25: 17500 | F25: =SUM(E25*D25) -> 17500 | I25: =SUM(H25*D25) -> 0
A26: 46218.072 | B26: Loutfat | C26: the minceur | D26: 1 | E26: 12500 | F26: =SUM(E26*D26) -> 12500 | H26: 2500 | I26: =SUM(H26*D26) -> 2500

Sheet TABLEAU DE BORD
A1: TABLEAU D ANALYSE
J22: TOLAL DEPENCE | M22: TOLAL DEPENCE

Sheet agent-num
A1: AGENT | B1: NUMERO | C1: PRODUİT 1 | D1: PRODUİT 2 | E1: ASSOCİE
A2: amine | B2: 4324464 | I2: 30-45 | J2: GAMME HUİLE
A3: asna | B3: 4541035 | C3: glorysmile | D3: GLORYSMİLE | G3: X | I3: 18-30
A4: balmata | B4: 4636761 | C4: prise de poids / | D4: savon au riz | E4: GLORYSMİLE-ASNA | F4: AYLAN SHOP | G4: X
A5: Ben Store | B5: 4554529 | C5: PRİSE DE POİDS | D5: SAVON AU RİZ | E5: JEL ORANGE-TAADHUMA | G5: X | H5: FEMME
A6: Boutique de Soin | B6: 4316190 | C6: JEL ORANGE | D6: PRİSE DE POİDS | E6: GLORYSMİLE-THAMARATİ | G6: X | H6: FEMME
A7: coach | B7: 4090831 | C7: moto
A8: fayrati | B8: 4463888 | C8: glorysmile | D8: PRİSE DE POİDS | E8: SAVON AU RİZ-HADİDJA | F8: 4870594 | G8: X | H8: djabiri
A9: Hadidja | B9: 4561858 | C9: parfum de bouche | D9: SAVON AU RİZ | G9: X
A10: hamida | B10: 3947053 | C10: savon au riz/ | D10: prise de poids | E10: JEL ORANGE -RABİANTİ | F10: AYLAN TREND | G10: X | H10: djabiri
A11: laila | B11: 3239302 | C11: AYLAN MARKET
A12: lutfat | B12: 4636772 | C12: jel orange/ | D12: prise de poids | E12: SAVON AU RİZ -BALMATA | F12: AYLAN SHOP | G12: X | H12: HOMME
A13: lutfia | B13: 4221767 | C13: glorysmile | D13: SAVON AU RİZ | G13: X
A14: malkia | B14: 4209873 | C14: GLORYSMİLE | D14: GEL ORANGE | G14: X | I14: 18-30 | J14: HUİLE GAMME
A15: Mariame | B15: 4080782 | C15: GLORYSMİLE | D15: GEL ORANGE | E15: PRİSE DE POİDS-BEN
A16: Mufti | B16: 4586158 | C16: THE MİNCEUR | D16: GLORYSMİLE | E16: SAVON AU RİZ-BEN | G16: X
A17: NADJMA | B17: 4476670 | H17: rahmatoullah
A18: nayla | B18: 4587817 | C18: jel orange / | D18: savon AU RİZ | E18: GLORYSMİLE-SURAYA | F18: AYLAN MARKET | G18: X
A19: rabianti | B19: 4937885 | C19: GLORYSMİLE | D19: GEL ORANGE | G19: X
A20: RACHİDA | B20: 4715137 | C20: AYLAN MARKET
A21: Raina | B21: 4587811 | C21: SAVON AU RİZ | D21: PARFUM DE BOUCHE | G21: X
A22: riwad | B22: 4559847 | C22: poudre de poids | D22: savon au riz | E22: JEL ORANGE-MARİAME | F22: AYLAN TREND | G22: X
A23: suraya | B23: 3330821 | C23: prise de poids | D23: GLORYSMİLE | E23: SAVON-RİWAD | F23: AYLAN MARKET | G23: X | H23: djabiri
A24: Thamarati | B24: 4348553 | C24: GLORYSMİLE | D24: PRİSE DE POİDS | E24: JEL ORANGE-LOUTFAT | G24: X

Sheet TEAMS
H2: PRODUİTS
A3: TAKWİM | B3: NOM | C3: NUMERO | D3: PRODUİT 1 | E3: PRODUİT 2 | F3: ASSOCİES | H3: CAFÉ | I3: 12500 | J3: X
B4: LOUTFAT | C4: 4636772 | D4: JEL ORANGE | E4: THE MİNCEUR | F4: DENTİFRİCE | H4: JEL ORANGE | I4: 12500 | J4: X
B5: NAYLA | C5: 4587817 | D5: THE MİNCEUR | E5: HAND CREAM | F5: DENTİFRİCE | H5: THE MİNCEUR | I5: 12500 | J5: X
H6: SNAKE OİL/CHAMPOİN | I6: 17500 | J6: X
H7: HAND CREAM | I7: 10000FC
A8: HADİDJA | B8: NOM | C8: NUMERO | D8: PRODUİT 1 | E8: PRODUİT 2 | F8: ASSOCİES | H8: DENTİFRİCE | I8: 8000/10000
B9: BEN | C9: 4554529 | D9: CAFÉ LONGRİCH | E9: JEL ORANGE
B10: THAMARATİ | C10: 4348553 | D10: SNAKE OİL | E10: HAND CREAM
A14: BOUSRİ | B14: NOM | C14: NUMERO | D14: PRODUİT 1 | E14: PRODUİT 2 | F14: ASSOCİES
B15: RİWAD | C15: 4559847 | D15: JEL ORANGE | E15: CAFÉ LONGRİCH | F15: P DENTİFRİCE | G15: VİTAMİN C
B16: MUFTİ | C16: 4586158 | D16: CAFÉ LONGRİCH | E16: THE MİNCEUR | F16: SAVON | G16: COLLAGENE
A19: RAMATOULLAH | B19: NOM | C19: NUMERO | D19: PRODUİT 1 | E19: PRODUİT 2 | F19: ASSOCİES
B20: MARİAME | C20: 4336877 | D20: THE MİNCEUR | E20: SNAKE OİL | F20: CALİCUİM
B21: KALATHOUME | C21: 4605616 | D21: SAKE OİL | E21: JEL ORANGE | F21: LAİT
A23: LOUTFİA | B23: NOM | C23: NUMERO | D23: PRODUİT 1 | E23: PRODUİT 2 | F23: ASSOCİES
B24: TAADHUMA | C24: 4316190 | D24: HAND CREAM | E24: CAFÉ LONGRİCH
A28: DALİLOU | B28: NOM | C28: NUMERO | D28: PRODUİT 1 | E28: PRODUİT 2 | F28: ASSOCİES
B29: SURAYA | C29: 3330821 | D29: CAFÉ | E29: SNAKE OİL
B30: FAİLOİTİ | C30: 4463888 | D30: THE MİNCEUR | E30: HAND CRAM
A32: TEAMS
A35: COMMUNES | B35: NOM | C35: NUMERO | D35: PRODUİT 1 | E35: PRODUİT 2
B36: BEN | C36: 4554529
B37: TAADHUMA | C37: 4316190
B38: THAMARATİ | C38: 4348553
B39: MOUFTİ
B40: NAYLA
B41: LOUTFAT
A43: COMMUNES | B43: NOM | C43: NUMERO | D43: PRODUİT 1 | E43: PRODUİT 2
